<?xml version="1.0"?>
<robot xmlns:xacro="http://ros.org/wiki/xacro">

<xacro:property name="PI" value="3.14159265359" />
<xacro:property name="cos_42" value="0.743144825" />
<xacro:property name="sin_42" value="0.669130606" />
<xacro:property name="SF" value="0.03937" /> <!-- Scale factor for meshes -->


<!-- LINKS -->

<!-- RIGHT ARM -->
<link name ="RShp">
    <inertial>
      <origin xyz="-0.00543349 -0.04480023 0.01581062" rpy="0 0 0"/>
      <mass value="1.81745527"/>
      <inertia ixx="0.00571053"  ixy="0.00041083"  ixz="-0.00005130" iyy="0.01126908" iyz="-0.00003461" izz="0.01371197" />
    </inertial>
    <visual>
      <origin xyz="0 0 0" rpy="0 0 0"/>
      <geometry name="RShp_visual">
        <mesh filename="package://bigman_urdf/meshes/ShoulderPitch.STL" scale="0.001 0.001 0.001" />
      </geometry>
    </visual>
    <collision>
      <origin xyz="0 0 0" rpy="0 0 0"/>
      <geometry name="RShp_collision">
        <mesh filename="package://bigman_urdf/meshes/simple/ShoulderPitch.STL" scale="0.001 0.001 0.001" />
      </geometry>             
    </collision>
</link>

<link name ="RShr">
    <inertial>
      <origin xyz="0.00729315 0.00002698 -0.07529696" rpy="0 0 0"/>
      <mass value="5.00486460"/>
      <inertia ixx="0.01644345"  ixy="-0.00001187"  ixz="-0.00010546" iyy="0.01804804" iyz="-0.00000565" izz="0.00802420" />
    </inertial>
    <visual>
      <origin xyz="0 0 0" rpy="0 0 0"/>
      <geometry name="RShr_visual">
        <mesh filename="package://bigman_urdf/meshes/TopUpperArm.STL" scale="0.001 0.001 0.001" />
      </geometry>
    </visual>
    <collision>
      <origin xyz="0 0 0" rpy="0 0 0"/>
      <geometry name="RShr_collision">
        <mesh filename="package://bigman_urdf/meshes/simple/TopUpperArm.STL" scale="0.001 0.001 0.001" />
      </geometry>             
    </collision>
</link>

<link name ="RShy">
    <inertial>
      <origin xyz="0.02765373 -0.03258647 -0.12698781" rpy="0 0 0"/>
      <mass value="3.20289133"/>
      <inertia ixx="0.01129046"  ixy="0.00013518"  ixz="-0.00134760" iyy="0.00984951" iyz="-0.00026836" izz="0.00728549" />
    </inertial>
    <visual>
      <origin xyz="0 0 0" rpy="0 0 0"/>
      <geometry name="RShy_visual">
        <mesh filename="package://bigman_urdf/meshes/BottomUpperArm.STL" scale="0.001 0.001 0.001" />
      </geometry>
    </visual>
    <collision>
      <origin xyz="0 0 0" rpy="0 0 0"/>
      <geometry name="RShy_collision">
        <mesh filename="package://bigman_urdf/meshes/simple/BottomUpperArm.STL" scale="0.001 0.001 0.001" />
      </geometry>             
    </collision>
</link>

<link name ="RElb">
        <inertial>
          <origin xyz="-6.5553403E-4 -9.3464748E-4 -9.3101289E-4" rpy="0 0 0"/>
          <mass value="0.63306933"/>
          <inertia ixx="2.2599075E-4"  ixy="-2.6376470E-7"  ixz="-9.8007285E-6" iyy="2.7781302E-4" iyz="-2.0435288E-6" izz="2.1878992E-4" />
        </inertial>
        <visual>
          <origin xyz="0 0 0" rpy="-1.570796326795 1.570796326795 0"/>
          <geometry name="RElb_visual">
            <mesh filename="package://bigman_urdf/meshes/collada/forearms/elbow.dae" scale="1.0 1.0 1.0" />
          </geometry>
        </visual>
        <collision>
          <origin xyz="0 0 0" rpy="-1.570796326795 1.570796326795 0"/>
          <geometry name="RElb_collision">
            <mesh filename="package://bigman_urdf/meshes/collada/simple/forearms/elbow.stl" scale="1.0 1.0 1.0" />
          </geometry>             
        </collision>
</link>

<!-- LEFT ARM -->
<link name ="LShp">
    <inertial>
      <origin xyz="-0.00543349 0.04480023 0.01581062" rpy="0 0 0"/>
      <mass value="1.81745527"/>
      <inertia ixx="0.00571053"  ixy="-0.00041083"  ixz="-0.00005130" iyy="0.01126908" iyz="0.00003461" izz="0.01371197" />
    </inertial>
    <visual>
      <origin xyz="0 0 0" rpy="0 0 0"/>
      <geometry name="RShp_visual">
        <mesh filename="package://bigman_urdf/meshes/ShoulderPitch.STL" scale="0.001 -0.001 0.001" />
      </geometry>
    </visual>
    <collision>
      <origin xyz="0 0 0" rpy="0 0 0"/>
      <geometry name="RShp_collision">
        <mesh filename="package://bigman_urdf/meshes/simple/ShoulderPitch.STL" scale="0.001 -0.001 0.001" />
      </geometry>             
    </collision>
</link>

<link name ="LShr">
    <inertial>
      <origin xyz="0.00729315 -0.00002698 -0.07529696" rpy="0 0 0"/>
      <mass value="5.00486460"/>
      <inertia ixx="0.01644345"  ixy="0.00001187"  ixz="-0.00010546" iyy="0.01804804" iyz="0.00000565" izz="0.00802420" />
    </inertial>
    <visual>
      <origin xyz="0 0 0" rpy="0 0 0"/>
      <geometry name="RShr_visual">
        <mesh filename="package://bigman_urdf/meshes/TopUpperArm.STL" scale="0.001 -0.001 0.001" />
      </geometry>
    </visual>
    <collision>
      <origin xyz="0 0 0" rpy="0 0 0"/>
      <geometry name="RShr_collision">
        <mesh filename="package://bigman_urdf/meshes/simple/TopUpperArm.STL" scale="0.001 -0.001 0.001" />
      </geometry>             
    </collision>
</link>

  <link name ="LShy">
    <inertial>
      <origin xyz="0.02765373 0.03258647 -0.12698781" rpy="0 0 0"/>
      <mass value="3.20289133"/>
      <inertia ixx="0.01129046"  ixy="-0.00013518"  ixz="-0.00134760" iyy="0.00984951" iyz="0.00026836" izz="0.00728549" />
    </inertial>
    <visual>
      <origin xyz="0 0 0" rpy="0 0 0"/>
      <geometry name="RShy_visual">
        <mesh filename="package://bigman_urdf/meshes/BottomUpperArm.STL" scale="0.001 -0.001 0.001" />
      </geometry>
    </visual>
    <collision>
      <origin xyz="0 0 0" rpy="0 0 0"/>
      <geometry name="RShy_collision">
        <mesh filename="package://bigman_urdf/meshes/simple/BottomUpperArm.STL" scale="0.001 -0.001 0.001" />
      </geometry>             
    </collision>
  </link>

    <link name ="LElb">
        <inertial>
          <origin xyz="-6.5553403E-4 9.3464748E-4 -9.3101289E-4" rpy="0 0 0"/>
          <mass value="0.63306933"/>
          <inertia ixx="2.2599075E-4"  ixy="2.6376470E-7"  ixz="-9.8007285E-6" iyy="2.7781302E-4" iyz="2.0435288E-6" izz="2.1878992E-4" />
        </inertial>
        <visual>
          <origin xyz="0 0 0" rpy="-1.570796326795 1.570796326795 0"/>
          <geometry name="LElb_visual">
            <mesh filename="package://bigman_urdf/meshes/collada/forearms/elbow.dae" scale="1.0 1.0 1.0" />
          </geometry>
        </visual>
        <collision>
          <origin xyz="0 0 0" rpy="-1.570796326795 1.570796326795 0"/>
          <geometry name="LElb_collision">
            <mesh filename="package://bigman_urdf/meshes/collada/simple/forearms/elbow.stl" scale="1.0 1.0 1.0" />
          </geometry>             
        </collision>
      </link>

<!-- JOINTS -->

<!-- RIGHT ARM -->
<joint name="RShSag" type="revolute">
    <parent link="DWYTorso"/>
    <child link="RShp"/>
    <origin xyz="0.0 -0.2 0.0" rpy="0 0 0" />
    <axis xyz="0 ${cos_42} ${-sin_42}" />
    <limit velocity="6.283" effort="120" lower="-2.844" upper="2.844" />
    <dynamics friction="0" damping="3.0"/>
</joint>

<joint name="RShLat" type="revolute">
    <parent link="RShp"/>
    <child link="RShr"/>
    <origin xyz="0.0 -0.116568264 0.03364" rpy="0 0 0" />
    <axis xyz="1 0 0" />
    <limit velocity="6.283" effort="120" lower="-3.699" upper="-0.052" />
    <dynamics friction="0" damping="3.0"/>
</joint>

<joint name="RShYaw" type="revolute">
    <parent link="RShr"/>
    <child link="RShy"/>
    <origin xyz="0.0 0.0 -0.222" rpy="0 0 0" />
    <axis xyz="0 0 1" />
    <limit velocity="6.283" effort="120" lower="-2.844" upper="2.844" />
    <dynamics friction="0" damping="3.0"/> 
</joint>

  <joint name="RElbj" type="revolute">
    <parent link="RShy"/>
    <child link="RElb"/>
    <origin xyz="0.036 0.0 -0.15" rpy="0 0 0" />
    <axis xyz="0 1 0" />
    <limit velocity="4.0" effort="50" lower="-2.3562" upper="0.0" />
    <dynamics friction="0" damping="3.0"/>
  </joint>

<!-- LEFT ARM -->
<joint name="LShSag" type="revolute">
    <parent link="DWYTorso"/>
    <child link="LShp"/>
    <origin xyz="0.0 0.2 0.0" rpy="0 0 0" />
    <axis xyz="0 ${cos_42} ${sin_42}" />
    <limit velocity="6.283" effort="120" lower="-2.844" upper="2.844" />
    <dynamics friction="0" damping="3.0"/>
</joint>

<joint name="LShLat" type="revolute">
    <parent link="LShp"/>
    <child link="LShr"/>
    <origin xyz="0.0 0.116568264 0.03364" rpy="0 0 0" />
    <axis xyz="1 0 0" />
    <limit velocity="6.283" effort="120" lower="0.052" upper="3.699" />
    <dynamics friction="0" damping="3.0"/>
</joint>

<joint name="LShYaw" type="revolute">
    <parent link="LShr"/>
    <child link="LShy"/>
    <origin xyz="0.0 0.0 -0.222" rpy="0 0 0" />
    <axis xyz="0 0 1" />
    <limit velocity="6.283" effort="120" lower="-2.844" upper="2.844" />
    <dynamics friction="0" damping="3.0"/>
</joint>

  <joint name="LElbj" type="revolute">
    <parent link="LShy"/>
    <child link="LElb"/>
    <origin xyz="0.036 0.0 -0.15" rpy="0 0 0" />
    <axis xyz="0 1 0" />
    <limit velocity="4.0" effort="50" lower="-2.3562" upper="0.0" />
    <dynamics friction="0" damping="3.0"/>
  </joint>

</robot>
