<?xml version="1.0"?>
<robot xmlns:xacro="http://ros.org/wiki/xacro">

<xacro:property name="mmTom" value="0.001" />
<xacro:property name="mm2Tom2" value="${0.001*0.001}" />
<xacro:property name="tonsToKg" value="1000.0" />

<xacro:property name="PI" value="3.14159265359" />
<xacro:property name="PI_2" value="1.57079632679" />
<xacro:property name="SF" value="0.03937" /> <!-- Scale factor for meshes -->

<!-- LINKS -->

<!-- ********************RIGHT LEG******************** -->

<link name ="RHipMot">
    <inertial>
      <origin xyz="${-1.0348188e+02*mmTom} ${-1.0919813e+02*mmTom} ${-6.4924056e+01*mmTom}" rpy="0 0 0"/>
      <mass value="${3.7958197e-03*tonsToKg}"/>
      <inertia ixx="${1.5639017e+01*mm2Tom2*tonsToKg}"  ixy="${1.8504661*mm2Tom2*tonsToKg}"  ixz="${2.3907793*mm2Tom2*tonsToKg}" iyy="${2.3519749e+01*mm2Tom2*tonsToKg}" iyz="${-2.3303162*mm2Tom2*tonsToKg}" izz="${2.0953643e+01*mm2Tom2*tonsToKg}" />
    </inertial>
    <visual>
      <origin xyz="0 0 0" rpy="0 0 0"/>
      <geometry name="RHipMot_visual">
        <mesh filename="package://bigman_urdf/meshes/HipRoll.STL" scale="0.001 0.001 0.001" />
      </geometry>
    </visual>
    <collision>
      <origin xyz="0 0 0" rpy="0 0 0"/>
      <geometry name="RHipMot_collision">
        <mesh filename="package://bigman_urdf/meshes/simple/HipRoll.STL" scale="0.001 0.001 0.001" />
      </geometry>             
    </collision>
</link>

  <link name ="RThighUpLeg">
    <inertial>
      <origin xyz="${-5.2929709*mmTom} ${-2.2561833e+01*mmTom} ${5.6701669*mmTom}" rpy="0 0 0"/>
      <mass value="3.2402068"/>
      <inertia ixx="${1.0102097e+04*mm2Tom2}"  ixy="${1.0858487e+02*mm2Tom2}"  ixz="${2.5291395e+02*mm2Tom2}" iyy="${6.7147000e+03*mm2Tom2}" iyz="${8.3447072e+01*mm2Tom2}" izz="${1.0485130e+04*mm2Tom2}" />
    </inertial>
    <visual>
      <origin xyz="0 0 0" rpy="0 0 0"/>
      <geometry name="RThighUpLeg_visual">
        <mesh filename="package://bigman_urdf/meshes/HipYaw.STL" scale="0.001 0.001 0.001" />
      </geometry>
    </visual>
    <collision>
      <origin xyz="0 0 0" rpy="0 0 0"/>
      <geometry name="RThighUpLeg_collision">
        <mesh filename="package://bigman_urdf/meshes/simple/HipYaw.STL" scale="0.001 0.001 0.001" />
      </geometry>             
    </collision>
  </link>

  <link name ="RThighLowLeg">
    <inertial>
      <origin xyz="${3.7746286e+01*mmTom} ${-2.8539939e+01*mmTom} ${-1.9310133e+02*mmTom}" rpy="0 0 0"/>
      <mass value="5.0950736"/>
      <inertia ixx="${5.1607858e+04*mm2Tom2}"  ixy="${2.2253472e+03*mm2Tom2}"  ixz="${2.4529790e+03*mm2Tom2}" iyy="${4.4349153e+04*mm2Tom2}" iyz="${-4.1006942e+03*mm2Tom2}" izz="${2.3374453e+04*mm2Tom2}" />
    </inertial>
    <visual>
      <origin xyz="0 0 0" rpy="0 0 0"/>
      <geometry name="RThighLowLeg_visual">
        <mesh filename="package://bigman_urdf/meshes/HipPitch.STL" scale="0.001 0.001 0.001" />
      </geometry>
    </visual>
    <collision>
      <origin xyz="0 0 0" rpy="0 0 0"/>
      <geometry name="RThighLowLeg_collision">
        <mesh filename="package://bigman_urdf/meshes/simple/HipPitch.STL" scale="0.001 0.001 0.001" />
      </geometry>             
    </collision>
  </link>

  <link name ="RLowLeg">
    <inertial>
      <origin xyz="0.0024612666 -0.0053099614 -0.08598948" rpy="0 0 0"/>
      <mass value="1.4098179"/>
      <inertia ixx="0.0040604004"  ixy="1.1227206E-5"  ixz="1.2260973E-5" iyy="0.004005652855" iyz="5.1899176E-4" izz="0.0012414054" />
    </inertial>
    <visual>
      <origin xyz="0.0 0.0726 -0.2942" rpy="0 0 ${PI}"/>
      <geometry name="RLowLeg_visual">
        <mesh filename="package://bigman_urdf/meshes/collada/asm0001_collada_17_prt.dae" scale="${SF} ${SF} ${SF}" />
      </geometry>
    </visual>
    <collision>
      <origin xyz="0.0 0.0726 -0.2942" rpy="0 0 ${PI}"/>
      <geometry name="RLowLeg_collision">
        <mesh filename="package://bigman_urdf/meshes/collada/simple/simple_asm0001_collada_17_prt.stl" scale="${SF} ${SF} ${SF}" />
      </geometry>             
    </collision>
  </link>

  <link name ="RFootmot">
    <inertial>
      <origin xyz="8.8067281E-4 -9.2224881E-4 2.3038476E-4" rpy="0 0 0"/>
      <mass value="0.72992131"/>
      <inertia ixx="3.2034425E-4"  ixy="7.6346303E-6"  ixz="2.5430158E-7" iyy="3.6584358E-4" iyz="-3.6889276E-6" izz="3.6065156E-4" />
    </inertial>
    <visual>
      <origin xyz="0.0 0.0726 -0.0932" rpy="0 0 ${PI}"/>
      <geometry name="RFootmot_visual">
        <mesh filename="package://bigman_urdf/meshes/collada/asm0001_collada_16_prt.dae" scale="${SF} ${SF} ${SF}" />
      </geometry>
    </visual>
    <collision>
      <origin xyz="0.0 0.0726 -0.0932" rpy="0 0 ${PI}"/>
      <geometry name="RFootmot_collision">
        <mesh filename="package://bigman_urdf/meshes/collada/simple/simple_asm0001_collada_16_prt.stl" scale="${SF} ${SF} ${SF}" />
      </geometry>             
    </collision>
  </link>

  <link name ="RFoot">
     <inertial>
        <origin xyz="0.01282904 -0.00463694 -0.10109499" rpy="0 0 0"/>
        <mass value="3.33109981"/>
        <inertia ixx="0.01006627"  ixy="-0.00051955"  ixz="-0.00374069" iyy="0.02882577" iyz="0.00044505" izz="0.02819025" />
      </inertial>
    <visual>
      <origin xyz="0 0 0" rpy="0 0 0"/>
      <geometry name="RFoot_visual">
        <mesh filename="package://bigman_urdf/meshes/Foot.STL" scale="0.001 -0.001 0.001"/>
      </geometry>
    </visual> 
    <collision>
      <origin xyz="0 0 0" rpy="0 0 0"/>
      <geometry name="RFoot_collision">
        <mesh filename="package://bigman_urdf/meshes/simple/Foot.STL" scale="0.001 -0.001 0.001"/>
      </geometry>             
    </collision>
  </link>


<!-- ********************LEFT LEG******************** -->
  <link name ="LHipMot">
    <inertial>
      <origin xyz="${-1.0348188e+02*mmTom} ${1.0919813e+02*mmTom} ${-6.4924056e+01*mmTom}" rpy="0 0 0"/>
      <mass value="${3.7958197e-03*tonsToKg}"/>
      <inertia ixx="${1.5639017e+01*mm2Tom2*tonsToKg}"  ixy="${-1.8504661*mm2Tom2*tonsToKg}"  ixz="${2.3907793*mm2Tom2*tonsToKg}" iyy="${2.3519749e+01*mm2Tom2*tonsToKg}" iyz="${2.3303162*mm2Tom2*tonsToKg}" izz="${2.0953643e+01*mm2Tom2*tonsToKg}" />
    </inertial>
    <visual>
      <origin xyz="0 0 0" rpy="0 0 0"/>
      <geometry name="RHipMot_visual">
        <mesh filename="package://bigman_urdf/meshes/HipRoll.STL" scale="0.001 -0.001 0.001" />
      </geometry>
    </visual>
    <collision>
      <origin xyz="0 0 0" rpy="0 0 0"/>
      <geometry name="RHipMot_collision">
        <mesh filename="package://bigman_urdf/meshes/simple/HipRoll.STL" scale="0.001 -0.001 0.001" />
      </geometry>             
    </collision>
  </link>

  <link name ="LThighUpLeg">
    <inertial>
      <origin xyz="${-5.2929709*mmTom} ${2.2561833e+01*mmTom} ${5.6701669*mmTom}" rpy="0 0 0"/>
      <mass value="3.2402068"/>
      <inertia ixx="${1.0102097e+04*mm2Tom2}"  ixy="${-1.0858487e+02*mm2Tom2}"  ixz="${2.5291395e+02*mm2Tom2}" iyy="${6.7147000e+03*mm2Tom2}" iyz="${-8.3447072e+01*mm2Tom2}" izz="${1.0485130e+04*mm2Tom2}" />
    </inertial>
    <visual>
      <origin xyz="0 0 0" rpy="0 0 0"/>
      <geometry name="RThighUpLeg_visual">
        <mesh filename="package://bigman_urdf/meshes/HipYaw.STL" scale="0.001 -0.001 0.001" />
      </geometry>
    </visual>
    <collision>
      <origin xyz="0 0 0" rpy="0 0 0"/>
      <geometry name="RThighUpLeg_collision">
        <mesh filename="package://bigman_urdf/meshes/simple/HipYaw.STL" scale="0.001 -0.001 0.001" />
      </geometry>             
    </collision>
  </link>

  <link name ="LThighLowLeg">
    <inertial>
      <origin xyz="${3.7746286e+01*mmTom} ${2.8539939e+01*mmTom} ${-1.9310133e+02*mmTom}" rpy="0 0 0"/>
      <mass value="5.0950736"/>
      <inertia ixx="${5.1607858e+04*mm2Tom2}"  ixy="${-2.2253472e+03*mm2Tom2}"  ixz="${2.4529790e+03*mm2Tom2}" iyy="${4.4349153e+04*mm2Tom2}" iyz="${4.1006942e+03*mm2Tom2}" izz="${2.3374453e+04*mm2Tom2}" />
    </inertial>
    <visual>
      <origin xyz="0 0 0" rpy="0 0 0"/>
      <geometry name="RThighLowLeg_visual">
        <mesh filename="package://bigman_urdf/meshes/HipPitch.STL" scale="0.001 -0.001 0.001" />
      </geometry>
    </visual>
    <collision>
      <origin xyz="0 0 0" rpy="0 0 0"/>
      <geometry name="RThighLowLeg_collision">
        <mesh filename="package://bigman_urdf/meshes/simple/HipPitch.STL" scale="0.001 -0.001 0.001" />
      </geometry>             
    </collision>
  </link>

  <link name ="LLowLeg">
    <inertial>
      <origin xyz="0.0024612666 0.0053099614 -0.085989484" rpy="0 0 0"/>
      <mass value="1.4098179"/>
      <inertia ixx="0.0040604004"  ixy="-1.1227206E-5"  ixz="1.2260973E-5" iyy="0.004005652855" iyz="-5.1899176E-4" izz="0.0012414054" />
    </inertial>
    <visual>
      <origin xyz="0.0 -0.0726 -0.2942" rpy="0 0 ${PI}"/>
      <geometry name="LLowLeg_visual">
        <mesh filename="package://bigman_urdf/meshes/collada/asm0001_collada_03_prt.dae" scale="${SF} ${SF} ${SF}" />
      </geometry>
    </visual>
    <collision>
      <origin xyz="0.0 -0.0726 -0.2942" rpy="0 0 ${PI}"/>
      <geometry name="LLowLeg_collision">
        <mesh filename="package://bigman_urdf/meshes/collada/simple/simple_asm0001_collada_03_prt.stl" scale="${SF} ${SF} ${SF}" />
      </geometry>             
    </collision>
  </link>

  <link name ="LFootmot">
    <inertial>
      <origin xyz="8.8067281E-4 9.2224881E-4 2.3038476E-4" rpy="0 0 0"/>
      <mass value="0.72992131"/>
      <inertia ixx="3.2034425E-4"  ixy="-7.6346303E-6"  ixz="2.5430158E-7" iyy="3.6584358E-4" iyz="3.6889276E-6" izz="3.6065156E-4" />
    </inertial>
    <visual>
      <origin xyz="0.0 -0.0726 -0.0932" rpy="0 0 ${PI}"/>
      <geometry name="LFootmot_visual">
        <mesh filename="package://bigman_urdf/meshes/collada/asm0001_collada_02_prt.dae" scale="${SF} ${SF} ${SF}" />
      </geometry>
    </visual>
    <collision>
      <origin xyz="0.0 -0.0726 -0.0932" rpy="0 0 ${PI}"/>
      <geometry name="LFootmot_collision">
        <mesh filename="package://bigman_urdf/meshes/collada/simple/simple_asm0001_collada_02_prt.stl" scale="${SF} ${SF} ${SF}" />
      </geometry>             
    </collision>
  </link>

  <link name ="LFoot">
      <inertial>
        <origin xyz="0.01282904 -0.00463694 -0.10109499" rpy="0 0 0"/>
        <mass value="3.33109981"/>
        <inertia ixx="0.01006627"  ixy="0.00051955"  ixz="-0.00374069" iyy="0.02882577" iyz="-0.00044505" izz="0.02819025" />
      </inertial>
      <visual>
      <origin xyz="0 0 0" rpy="0 0 0"/>
      <geometry name="LFoot_visual">
        <mesh filename="package://bigman_urdf/meshes/Foot.STL" scale="0.001 0.001 0.001"/>
      </geometry>
    </visual> 
    <collision>
      <origin xyz="0 0 0" rpy="0 0 0"/>
      <geometry name="LFoot_collision">
        <mesh filename="package://bigman_urdf/meshes/simple/Foot.STL" scale="0.001 0.001 0.001"/>
      </geometry>             
    </collision>
   </link>



<!-- JOINTS -->

<!-- ********************RIGHT LEG******************** -->

  <joint name="RHipSag" type="revolute">
    <parent link="Waist"/>
    <child link="RHipMot"/>
    <origin xyz="0.1059 -0.06 0.0" rpy="0 0 0" />
    <axis xyz="1 0 0" />
    <limit velocity="4.0" effort="50" lower="-1.9199" upper="0.7854" />
    <dynamics friction="0" damping="3.0"/>
  </joint>

  <joint name="RHipLat" type="revolute">
    <parent link="RHipMot"/>
    <child link="RThighUpLeg"/>
    <origin xyz="-0.0889 -0.121032 -0.217872" rpy="0 0 0" />
    <axis xyz="0 0 1" />
    <limit velocity="4.0" effort="50" lower="-1.0472" upper="0.4363" />
    <dynamics friction="0" damping="3.0"/>
  </joint>

  <joint name="RHipYaw" type="revolute">
    <parent link="RThighUpLeg"/>
    <child link="RThighLowLeg"/>
    <origin xyz="0.0 0.0 0.0" rpy="0 0 0" />
    <axis xyz="0 1 0" />
    <limit velocity="4.0" effort="50" lower="-0.8727" upper="0.8727" />
    <dynamics friction="0" damping="3.0"/>
  </joint>

  <joint name="RKneeSag" type="revolute">
    <parent link="RThighLowLeg"/>
    <child link="RLowLeg"/>
    <origin xyz="0.0 0.0 -0.356" rpy="0 0 0" />
    <axis xyz="0 1 0" />
    <limit velocity="4.0" effort="50" lower="-0.1745" upper="1.9199" />
    <dynamics friction="0" damping="3.0"/>
  </joint>

  <joint name="RAnkLat" type="revolute">
    <parent link="RLowLeg"/>
    <child link="RFootmot"/>
    <origin xyz="0.0 0.0 -0.201" rpy="0 0 0" />
    <axis xyz="1 0 0" />
    <limit velocity="4.0" effort="50" lower="-0.6109" upper="0.6109" />
    <dynamics friction="0" damping="3.0"/> 
  </joint>

    <joint name="RAnkSag" type="revolute">
      <parent link="RFootmot"/>
      <child link="RFoot"/>
      <origin xyz="0.0 0.0 0.0" rpy="0 0 0" />
      <axis xyz="0 1 0" />
      <limit velocity="4.0" effort="50" lower="-1.2217" upper="1.2217" />
      <dynamics friction="0" damping="3.0"/>
    </joint>


<!-- ********************LEFT LEG******************** -->

  <joint name="LHipSag" type="revolute">
    <parent link="Waist"/>
    <child link="LHipMot"/>
    <origin xyz="0.1059 0.06 0.0" rpy="0 0 0" />
    <axis xyz="1 0 0" />
    <limit velocity="4.0" effort="50" lower="-1.9199" upper="0.7854" />
    <dynamics friction="0" damping="3.0"/>
  </joint>

  <joint name="LHipLat" type="revolute">
    <parent link="LHipMot"/>
    <child link="LThighUpLeg"/>
    <origin xyz="-0.0889 0.121032 -0.217872" rpy="0 0 0" />
    <axis xyz="0 0 1" />
    <limit velocity="4.0" effort="50" lower="-0.4363" upper="1.0472" />
    <dynamics friction="0" damping="3.0"/>
  </joint>

  <joint name="LHipYaw" type="revolute">
    <parent link="LThighUpLeg"/>
    <child link="LThighLowLeg"/>
    <origin xyz="0.0 0.0 0.0" rpy="0 0 0" />
    <axis xyz="0 1 0" />
    <limit velocity="4.0" effort="50" lower="-0.8727" upper="0.8727" />
    <dynamics friction="0" damping="3.0"/>
  </joint>

  <joint name="LKneeSag" type="revolute">
    <parent link="LThighLowLeg"/>
    <child link="LLowLeg"/>
    <origin xyz="0.0 0.0 -0.356" rpy="0 0 0" />
    <axis xyz="0 1 0" />
    <limit velocity="4.0" effort="50" lower="-0.1745" upper="1.9199" />
    <dynamics friction="0" damping="3.0"/>
  </joint>

  <joint name="LAnkLat" type="revolute">
    <parent link="LLowLeg"/>
    <child link="LFootmot"/>
    <origin xyz="0.0 0.0 -0.201" rpy="0 0 0" />
    <axis xyz="1 0 0" />
    <limit velocity="4.0" effort="50" lower="-0.6109" upper="0.6109" />
    <dynamics friction="0" damping="3.0"/>
  </joint>

  <joint name="LAnkSag" type="revolute">
    <parent link="LFootmot"/>
    <child link="LFoot"/>
    <origin xyz="0.0 0.0 0.0" rpy="0 0 0" />
    <axis xyz="0 1 0" />
    <limit velocity="4.0" effort="50" lower="-1.2217" upper="1.2217" />
    <dynamics friction="0" damping="3.0"/>
  </joint>


</robot>
